Workbook

Sheet Inputs & Geometry
A1: Name | B1: Value | C1: Unit | D1: Formulas Used
A2: Area_A_farm | B2: 70000 | C2: ha
A3: Tortuosity_tau_A | B3: 1.5 | C3: _
A5: M_maize | B5: 250000 | C5: Mg/year
A6: Y_maize | B6: 40 | C6: Mg/ha/year
A7: Arable_fraction | B7: 0.21 | C7: _
A8: Energy_maize_fraction | B8: 0.25 | C8: _
A9: Tortuosity_tau_B | B9: 1.5 | C9: _
A10: Annual_green_gas | B10: 17021869 | C10: m^3/year
A12: Area_A | B12: =B2*10000 -> 700000000 | C12: m^2
A13: R_A | B13: =SQRT(B12/PI()) -> 14927.053 | C13: m | D13: SQRT(Area_A/Pi)
A14: Rahd_A | B14: =B3*(2/3)*B13 -> 14927.053 | C14: m | D14: R_A*(2/3)*Tortuosity_A
A16: A_maize | B16: =B2 -> 70000 | C16: ha | D16: M_maize/Y_maize
A17: Maize_land_fraction | B17: =B7*B8 -> 0.0525 | D17: Arable_fraction*Energy_maize_fraction
A18: A_total | B18: 733 | C18: ha | D18: A_maize/Maize_land_fraction
A19: A_total | B19: =B18*10000 -> 7330000 | C19: m^2 | D19: A_total*10000
A20: R_tot | B20: =SQRT(B19/PI()) -> 1527.4853 | C20: m | D20: SQRT(A_total/Pi)
A21: Rahd_B | B21: =B9*(2/3)*B20*((1-(B13/B20)^3)/(1-(B13/B20)^2)) -> 15068.851 | C21: m | D21: Tortuosity_B*(2/3)*R_tot*((1-(R_A/R_tot)^3)/(1-(R_A/R_tot)^2))

Sheet Maize Transport
A1: Parameter | B1: Value | C1: Unit | D1: Formualas Used
A2: Tractor_capacity | B2: 14 | C2: ton
A3: Truck_capacity | B3: 30 | C3: ton
A4: Tractor_cost | B4: 0.85 | C4: €/Km
A5: Truck_cost | B5: 1.24 | C5: €/Km
A6: Energy_consumption_tractor_transport | B6: 2.1 | C6: MJ/(ton.Km)
A7: Energy_consumption_truck_transport | B7: 1.3 | C7: MJ/(ton.Km)
A9: Rahd_A | B9: ='Inputs & Geometry'!B14/1000 -> 14.927053 | C9: Km
A10: Rahd_B | B10: ='Inputs & Geometry'!B21/1000 -> 15.068851 | C10: Km
A12: Biomass_total | B12: ='Inputs & Geometry'!B5 -> 250000 | C12: ton/year
A14: Description | B14: Value | C14: Unit
A15: Tractor_trips | B15: =B12/B2 -> 17857.143 | D15: Biomass_total/Tractor_capacity
A16: Tractor_tonkm | B16: =B12*B9 -> 3731763.3 | C16: ton-Km/year | D16: Biomass_total*Rahd_A
A17: Tractor_energy | B17: =B16*B6 -> 7836703 | C17: MJ/year | D17: Tractor_tonkm*Energy_consumption_tractor_transport
A18: Tractor_cost | B18: =B15*B9*B4*2 -> 453142.69 | C18: €/year | D18: Tractor_trips*Rahd_A*Tractor_cost*2
A21: Truck_trips | B21: =B12/B3 -> 8333.3333 | D21: Biomass_total/Truck_capacity
A22: Truck_tonkm | B22: =B12*B10 -> 3767212.7 | C22: ton-Km/year | D22: Biomass_total*Rahd_B
A23: Truck_energy | B23: =B22*B7 -> 4897376.5 | C23: MJ/year | D23: Truck_tonkm*Energy_consumption_truck_transport
A24: Truck_cost | B24: =B21*B10*B5*2 -> 311422.92 | C24: €/year | D24: Truck_trips*Rahd_B*Truck_cost*2
A26: Total_energy | B26: =B17+B23 -> 12734079 | C26: MJ/year | D26: Tractor_energy + Truck_energy
A27: Total_cost | B27: =B18+B24 -> 764565.6 | C27: €/year | D27: Tractor_cost + Truck_cost
A29: Annual_Green_gas | B29: =B12*0.3*0.93*650*0.7*0.52 -> 16502850 | C29: m^3/year | E29: only for Maize
A30: Energy | B30: =B26/B29 -> 0.77162911 | C30: MJ/m^3 | D30: Total_energy/Annual_Green_gas
A31: Cost | B31: =B27/B29 -> 0.046329307 | C31: €/m^3 | D31: Total_cost/Annual_Green_gas
A32: Cost_euro_cnt | B32: =B31*100 -> 4.6329307 | C32: €ct/m^3 | D32: cost*100

Sheet Manure
A1: Description | B1: Value | C1: Unit | D1: Formulas Used
A2: No. of cows | B2: 5149
A3: manure production dairy cattle | B3: 10 | C3: ton/year/cow
A4: Manure_used | B4: =B2*B3 -> 51490 | C4: ton/year
A5: Manure_price | B5: -15 | C5: €/ton
A7: Annual_manure_cost | B7: =B4*B5 -> -772350 | C7: €/year | D7: Manure_used*Manure_price
A8: Annual_green_gas | B8: ='Inputs & Geometry'!B10 -> 17021869 | C8: m³/year
A9: Manure_cost_per_m3 | B9: =B7/B8 -> -0.045373983 | C9: €/m³ | D9: Annual_manure_cost/Annual_green_gas
A10: Manure_cost_ct_per_m3 | B10: =B9*100 -> -4.5373983 | C10: ct/m³ | D10: Manure_cost_per_m3*100

Sheet Cosubstrate
A1: Description | B1: Value | C1: Unit | D1: Formulas Used
A2: Cosubstrate_mass | B2: ='Digester Biogas'!B3 -> 250000 | C2: ton/year
A3: Cosubstrate_price | B3: 13.5 | C3: €/ton
A5: Annual_cosubstrate_cost | B5: =B2*B3 -> 3375000 | C5: €/year | D5: cosubstrate_mass*cosubstrate_price
A6: Annual_green_gas | B6: ='Inputs & Geometry'!B10 -> 17021869 | C6: m³/year
A7: Cosubstrate_cost_per_m3 | B7: =B5/B6 -> 0.19827435 | C7: €/m³ | D7: Annula_cosubstarte_cost/Annual_Green_gas
A8: Cosubstrate_cost_ct_per_m3 | B8: =B7*100 -> 19.827435 | C8: €ct/m³ | D8: cosubstarte_cost_per_m3*100
A10: Cosubstrate_energy_intensity | B10: 37 | C10: MJ/ton
A12: Annual_cosubstrate_energy | B12: =B2*B10 -> 9250000 | C12: MJ/year | D12: cosubstrate_mass*cosubstrate_energy_intensity
A13: Annual_green_gas | B13: ='Inputs & Geometry'!B10 -> 17021869 | C13: m³/year
A14: Cosubstrate_energy_per_m3 | B14: =B12/B13 -> 0.54341859 | C14: MJ/m³ | D14: Annual_cosubstrate_energy/Annual_Green_gas

Sheet Manure Transport
A1: Description | B1: Value | C1: Unit | D1: Formulas Used
A3: Truck_capacity | B3: 30 | C3: ton
A4: Truck_cost | B4: 1.24 | C4: €/km
A5: Truck_energy | B5: 1.3 | C5: MJ/(ton·km)
A7: Manure_per_cow | B7: =Manure!B3 -> 10 | C7: ton/year/cow
A8: Number_of_cows | B8: =Manure!B2 -> 5149
A9: Total_manure | B9: =B7*B8 -> 51490 | C9: ton/year | D9: Manure_per_cows*Number_of_cows
A11: Rahd_A | B11: ='Inputs & Geometry'!B14/1000 -> 14.927053
A12: Rahd_B | B12: ='Inputs & Geometry'!B21/1000 -> 15.068851 | C12: Km
A14: Truck_trips | B14: =B9/B3 -> 1716.3333 | C14: trips/year | D14: Total_manure/Truck_capacity
A15: Truck_tonkm | B15: =B9*B12 -> 775895.12 | C15: ton·km/year | D15: Total_manure*Manure_distance_km
A16: Truck_energy_total | B16: =B15*B5 -> 1008663.7 | C16: MJ/year | D16: Truck_tonkm*Truck_energy
A17: Truck_cost_total | B17: =B14*B12*B4*2 -> 64140.664 | C17: €/year | D17: Truck_trips*Manure_distance_km*Truck_cost*2
A19: Annual_green_gas | B19: =B9*0.12*0.8*250*0.7*0.6 -> 519019.2 | C19: m³/year | E19: only for Manure
A21: Manure_energy_MJ_per_m3 | B21: =B16/B19 -> 1.9434034 | C21: MJ/m³ | D21: Truck_energy_total/Annual_green_gas
A22: Manure_cost_EUR_per_m3 | B22: =B17/B19 -> 0.12358052 | C22: €/m³ | D22: Truck_cost_total/Annual_Green_gas
A23: Manure_cost_EUR_per_m3 | B23: =B22*100 -> 12.358052 | C23: €ct/m^3 | D23: Manure_cost_EUR_per_m3*100

Sheet Digestate Transport
A1: Description | B1: Value | C1: Unit
A3: Truck_capacity | B3: 30 | C3: ton
A4: Truck_cost | B4: 1.24 | C4: €/km
A5: Truck_energy | B5: 1.3 | C5: MJ/(ton·km)
A7: Digestate_from_maize | B7: ='Maize Transport'!B12 -> 250000 | C7: ton/year
A8: Digestate_from_manure | B8: ='Manure Transport'!B9 -> 51490 | C8: ton/year
A9: Total_digestate | B9: =B7+B8 -> 301490 | C9: ton/year
A11: Digestate_distance_km | B11: ='Inputs & Geometry'!B21/1000 -> 15.068851
A13: Digestate_trips | B13: =B9/B3 -> 10049.667
A14: Digestate_tonkm | B14: =B9*B11 -> 4543107.8
A15: Digestate_energy | B15: =B14*B5 -> 5906040.2
A16: Digestate_cost | B16: =B13*B11*B4*2 -> 375563.58
A18: Annual_green_gas | B18: ='Inputs & Geometry'!B10 -> 17021869
A19: Digestate_energy_MJ_per_m3 | B19: =B15/B18 -> 0.34696778
A20: Digestate_cost_EUR_per_m3 | B20: =B16/B18 -> 0.022063592
A21: Digestate_cost_EUR_per_m3 | B21: =B20*100 -> 2.2063592 | C21: €ct/m^3

Sheet Digester Biogas
A1: Description | B1: Value | C1: Unit
A2: Manure_input | B2: ='Manure Transport'!B9 -> 51490 | C2: ton/year
A3: Maize_input | B3: ='Maize Transport'!B12 -> 250000 | C3: ton/year
A5: Biogas_yield_manure | B5: =0.12*0.8*250*0.7 -> 16.8 | C5: m3/ton
A6: Biogas_yield_maize | B6: =0.3*0.93*650*0.7 -> 126.945 | C6: m3/ton
A8: Biogas_from_manure | B8: =B2*B5 -> 865032 | C8: m3/year
A9: Biogas_from_maize | B9: =B3*B6 -> 31736250 | C9: m3/year
A10: Total_biogas | B10: =B8+B9 -> 32601282 | C10: m3/year
A12: Methane_content_biogas | B12: 0.556
A13: Methane_raw | B13: =B10*B12 -> 18126313 | C13: m3/year

Sheet Digestate Handling
A1: Description | B1: Value | C1: Unit
A2: Digestate_mass | B2: ='Digester Biogas'!B2 + 'Digester Biogas'!B3 -> 301490 | C2: ton/year
A3: Fertilizer_saving | B3: 3 | C3: €/ton
A5: Annual_digestate_credit | B5: =B2*B3 -> 904470 | C5: €/year
A6: Annual_green_gas | B6: ='Inputs & Geometry'!B10 -> 17021869 | C6: m³/year
A7: Digestate_credit_per_m3 | B7: =B5/B6 -> 0.053135763 | C7: €/m³
A8: Digestate_credit_ct_per_m3 | B8: =B7*100 -> 5.3135763 | C8: €ct/m³

Sheet Digester
A1: Description | B1: Value | C1: Unit | E1: Assumptions: | G1: Formula/ Equation | H1: Unit
A2: Operating hours | B2: 8000 | C2: h/year | E2: Slurry density = 1000 kg/m³ | F2: Total Digester Energy = Heating + Mixing + Pumping
A4: Annual production of biogas | B4: 32601282 | C4: m³/year
A5: Annual production of biogas | B5: =B4/8000 -> 4075.1602 | C5: m³/h
A6: Annual production of green gas | B6: 17021869 | C6: m³/year | E6: Cp = 4.18 kJ/kg*K | F6: E_total = E_heating + E_mixing + E_pumping
E7: T1 = 308.15 K
A8: Investment of 1 digester | B8: 2025000 | C8: € | D8: 0.0082*Q^0.9042*106 | E8: T2 = 288.15 K | F8: Q | G8: m*Cp*( T1 - T2)
A9: Investment of 6 digester | B9: =0.0082 * (B5^0.9042) * 10^6 -> 15069772 | C9: € | F9: Q | G9: 1000 * 4.18*20
E10: Typical mixing requirement: | F10: Q | G10: 83.6 | H10: MJ/m³
A11: Depreciation period | B11: 12 | C11: years | E11: 5–10 W per m³ of digester volume
A12: OPEX | B12: 0.05
F13: 1 m³ biogas | G13: 70 | H13: kg slurry
A14: Annual Depreciation cost | B14: =B9/B11 -> 1255814.3 | C14: €/year | F14: E_heating | G14: =G10 / G13 -> 1.1942857 | H14: MJ/m³
A15: Annual OPEX | B15: =B9*B12 -> 753488.6 | C15: €/year | F15: E_mixing | G15: 0.03 | H15: MJ/m³
F16: E_pumping | G16: 0.015 | H16: MJ/m³
A17: Total Cost | B17: =B14 + B15 -> 2009302.9 | C17: €/year
F18: E_total | G18: =G14+G15+G16 -> 1.2392857 | H18: MJ/m³
A19: Cost per m³ | B19: =B17 / B6 -> 0.11804244 | C19: €/ m³
A20: Cost per m³ | B20: =B19*100 -> 11.804244 | C20: €ct/m³

Sheet Biogass grid
A1: Parameter | B1: Value | C1: Unit | D1: Formula
A2: Number of digesters | B2: 6 | C2: -
A3: Biogas per digester | B3: =Digester!B5/6 -> 679.19337 | C3: m3/hr
A4: Radius | B4: =SQRT(700/22*7) -> 14.92405 | C4: km
A5: Pipeline diameter | B5: 110 | C5: mm
A6: Easy terrain fraction | B6: 0.6 | C6: -
A7: Difficult terrain fraction | B7: 0.4 | C7: -
A8: Pipeline cost easy | B8: 40 | C8: €/m
A9: Pipeline cost difficult | B9: 160 | C9: €/m
A10: Compressors needed | B10: =B2-1 -> 5 | C10: - | D10: Number digesters - 1
A11: Electricity price | B11: 0.14 | C11: €/kWh
A13: pipeline
A14: Pipeline length per digester | B14: =2*B4 -> 29.8481 | C14: km | D14: 2 × Radius
A15: Total pipeline length | B15: =B14*B10 -> 149.2405 | C15: km | D15: Length per digester × compressors
A16: Total pipeline length (m) | B16: =B15*1000 -> 149240.5 | C16: m | D16: km to m
A17: Average pipeline cost per m | B17: =B6*B8+B7*B9 -> 88 | C17: €/m | D17: weighted average
A19: Pipeline cost | B19: =(B16*B17) -> 13133164 | C19: € | D19: length × cost per m
A20: Maintenance | B20: =0.02*B19 -> 262663.28
A22: required investments::
A23: Desulfurization + drying | B23: 5000 | C23: € | D23: per digester
A24: total | B24: =B2*B23 -> 30000 | C24: €
A25: Flare cost | B25: 100000 | C25: €
A26: Total additional cost: | B26: =B24+B25 -> 130000 | C26: €
A28: TOTAL PIPE | B28: =B19+B20+B26 -> 13525827
A30: Compressor cost per unit | B30: =111.257+0.1469*(B3) -> 211.03051 | C30: € | D30: paper formula
A31: OPEX | B31: =0.05*B30 -> 10.551525
A33: Total compressor Cost | B33: =(B30+B31)*B10 -> 1107.9102 | C33: € | D33: per compressor × number
A36: Total grid Cost | B36: =B28+B33 -> 13526935 | C36: € | D36: pipeline + compressor
A38: Annual pipeline Cost | B38: =B28/12 -> 1127152.3 | C38: €/year | D38: 12 year depreciation
A39: Annual compressor cost | B39: =B33/12 -> 92.325847 | C39: €/year | D39: 12 year depreciation
A40: Total annual cost | B40: =B39+B38 -> 1127244.6 | C40: €/year | D40: sum
A42: Total annual biogas grid cost | B42: =B40 -> 1127244.6 | C42: €/year
A43: Annual biogas production | B43: =B3*8000*6 -> 32601282 | C43: m3/year | D43: flow × digesters × hours
A44: Cost per m³ | B44: =B42/B43 -> 0.034576696 | C44: €/m3
B47: ENERGY CALCULATION
A48: ID | B48: 0.09 | C48: m
A49: ID in mm | B49: 90 | C49: mm
A50: VISCOSITY | B50: 1.21e-05 | C50: Pa.s
A51: roughness | B51: 0.1 | C51: mm
A54: 1.velocity (Q/A) | B54: =(B3/3600)/(PI()*(0.09/2)^2) -> 29.656237
...

Sheet Upgrading
A1: Technical Variables | B1: Value | C1: Unit | D1: Formula
A2: Biogas capacity | B2: =Digester!B5 -> 4075.1602 | C2: m³/h
A3: Operating hours | B3: 8000 | C3: h/year
A4: Annual green gas | B4: =Digester!B6 -> 17021869 | C4: m³/year | D4: Green gas capacity * Operating hours
A5: Number of digesters | B5: 6
A7: Financial Parameters | B7: Value | C7: Unit | D7: Formula
A8: Depreciation period (n) | B8: 12 | C8: year
A9: Interest rate [r] | B9: 0.07
A10: O&M fraction | B10: 0.05
A12: Investment Cost | B12: =81532*B2^(0.4551) -> 3583479.7 | C12: € | D12: 81532 * Q^(0.4551)
A13: Capital Recovery Factor(CRF) | B13: 0.1128 | D13: [r*(1+r)n]/[(1+r)n - 1]
A14: Annualized CAPEX | B14: =B12*B13 -> 404216.51 | C14: €/year | D14: Investment Cost * CRF
A16: O&M Cost | B16: =B12 * B10 -> 179173.98 | C16: €/year | D16: Investment Cost * O&M fraction
A18: Specific Energy Consumption | B18: 0.408 | C18: kWh/m³
A19: Electricity price | B19: 0.14 | C19: €/kWh
A21: Annual Energy Use | B21: =B4*B18 -> 6944922.6 | C21: kWh/year | D21: Annual production * Specific Energy Consumption
A22: Energy use per m3 | B22: =(3.6 * B21)/B4 -> 1.4688 | C22: MJ/m3 | D22: Annual Energy use / Annual Production
A24: Annual Energy Cost | B24: =B19*B21 -> 972289.17 | C24: €/year | D24: Annual Energy Use * Electricity price
A25: Total Annual Upgrading Cost | B25: =B14+B16+B24 -> 1555679.7 | C25: €/year | D25: Annual Energy Use + O&M Cost + Annualized CAPEX
A27: Upgrading Cost per m³ | B27: =B25/B4 -> 0.091392998 | C27: €/m3 | D27: Total Annual Upgrading Cost / Annual production
A29: Upgrading Cost | B29: =B27*100 -> 9.1392998 | C29: €ct/m3 | D29: Upgrading Cost per m³ * 100

Sheet Injection Right
A1: Description | B1: Investment | D1: Unit | H1: Formulaes Used | I1: Assumptions
A2: Annual green gas | B2: 17021869 | D2: m^3/year
A3: Operating hours | B3: 8000 | D3: h/year | H3: Annual depreciation = Investment ÷ 12 years
A4: Green gas capacity | B4: =B2/B3 -> 2127.7337 | D4: m³/h | H4: Annual interest = Investment × 7%
H5: Opex = Investment × 5%/year
A6: CAPITAL COSTS | H6: Total annual cost = Depreciation + Interest + Opex
A7: Distance installation to grid | B7: 500 | D7: m
A8: Piping costs | B8: 130 | D8: €/m
A10: Fixed cost for injection point | B10: 200000 | D10: €
A11: Injection investment | B11: =B7*B8 -> 65000 | D11: € | H11: Cost ct/m³ = (Total annual cost ÷ 1,200,000 m³) × 100
A13: Total Injection Cost | B13: =B10+B11 -> 265000 | D13: €
A15: Annual depreciation | B15: =B13/12 -> 22083.333 | D15: €/year
A16: Annual interest | B16: =B13*0.07 -> 18550 | D16: €/year
A18: OPERATING COSTS
A19: Opex | B19: =B13*0.05 -> 13250 | D19: €/year
A22: TOTAL ANNUAL COST | B22: =B19+B16+B15 -> 53883.333 | D22: €/year
A24: Injection Cost per m³ | B24: =B22/B2 -> 0.0031655356
A26: Injection cost | B26: =B24*100 -> 0.31655356 | D26: €ct/m³
A29: Specific Energy Consumption | B29: 0.07 | C29: kWh/m³
A30: Electricity price | B30: 0.14 | C30: €/kWh
A32: Annual Energy Use | B32: =B29*B2 -> 1191530.8 | C32: kWh/year | D32: Annual production * Specific Energy Consumption
A33: Energy use per m3 | B33: =(3.6 * B32)/B2 -> 0.252 | C33: MJ/m3 | D33: Annual Energy use / Annual Production
